<?xml version="1.0" ?>
<!-- =================================================================================== -->
<!-- |    This document was autogenerated by xacro from hunter.urdf.xacro              | -->
<!-- |    EDITING THIS FILE BY HAND IS NOT RECOMMENDED                                 | -->
<!-- =================================================================================== -->
<!-- 组合小车底盘与摄像头与雷达 -->
<robot name="hunter">
  <gazebo>
    <plugin filename="libgazebo_ros_control.so" name="gazebo_ros_control">
      <robotSimType>steer_bot_hardware_gazebo/SteerBotHardwareGazebo</robotSimType>
      <legacyModeNS>false</legacyModeNS>
    </plugin>
  </gazebo>
  <link name="base_link">
    <inertial>
      <origin rpy="0 0 0" xyz="0 0 0"/>
      <mass value="17.26"/>
      <inertia ixx="0.134628" ixy="0" ixz="0" iyy="0.134628" iyz="0" izz="0.2589"/>
    </inertial>
    <visual>
      <geometry>
        <box size="0.3 0.3 0.06"/>
      </geometry>
      <origin rpy="0.0 0.0 0.0" xyz="0.0 0.0 0.0"/>
    </visual>
    <collision>
      <geometry>
        <box size="0.3 0.3 0.06"/>
      </geometry>
      <origin rpy="0.0 0.0 0.0" xyz="0.0 0.0 0.0"/>
    </collision>
  </link>
  <!-- <link name="base_footprint">
      <visual>
        <geometry>
          <sphere radius="${base_footprint_radius}" />
        </geometry>
      </visual>
    </link>
    <joint name="base_link2base_footprint" type="fixed">
      <parent link="base_footprint" />
      <child link="base_link" />
      <origin xyz="0 0 ${wheel_radius - high / 2 }" />
    </joint> -->
  <!--left flag=1-->
  <!--right flag=-1-->
  <link name="left_rear_link">
    <inertial>
      <origin rpy="1.5707963265 0 0" xyz="0 0 0"/>
      <mass value="0.2963"/>
      <inertia ixx="0.00031157796875000003" ixy="0" ixz="0" iyy="0.00031157796875000003" iyz="0" izz="0.0005787109375"/>
    </inertial>
    <visual>
      <origin rpy="0 0 0" xyz="0 0 0"/>
      <geometry>
        <mesh filename="package://hunter_gazebo/meshes/front_left_wheel_link.STL"/>
      </geometry>
      <material name="black">
        <color rgba="0.0 0.0 0.0 1.0"/>
      </material>
    </visual>
    <collision>
      <origin rpy="0 0 0" xyz="0 0 0"/>
      <geometry>
        <mesh filename="package://hunter_gazebo/meshes/front_left_wheel_link.STL"/>
      </geometry>
    </collision>
  </link>
  <gazebo reference="left_rear_link">
    <material>Gazebo/Black</material>
  </gazebo>
  <joint name="left_rear_joint" type="continuous">
    <origin rpy="0 0 0" xyz="-0.15 0.21 0"/>
    <parent link="base_link"/>
    <child link="left_rear_link"/>
    <axis xyz="0 1 0"/>
    <limit effort="0" lower="-3.14" upper="3.14" velocity="0"/>
  </joint>
  <gazebo reference="left_wheel">
    <material>Gazebo/Red</material>
  </gazebo>
  <!--left flag=1-->
  <!--right flag=-1-->
  <link name="right_rear_link">
    <inertial>
      <origin rpy="1.5707963265 0 0" xyz="0 0 0"/>
      <mass value="0.2963"/>
      <inertia ixx="0.00031157796875000003" ixy="0" ixz="0" iyy="0.00031157796875000003" iyz="0" izz="0.0005787109375"/>
    </inertial>
    <visual>
      <origin rpy="0 0 0" xyz="0 0 0"/>
      <geometry>
        <mesh filename="package://hunter_gazebo/meshes/front_right_wheel_link.STL"/>
      </geometry>
      <material name="black">
        <color rgba="0.0 0.0 0.0 1.0"/>
      </material>
    </visual>
    <collision>
      <origin rpy="0 0 0" xyz="0 0 0"/>
      <geometry>
        <mesh filename="package://hunter_gazebo/meshes/front_right_wheel_link.STL"/>
      </geometry>
    </collision>
  </link>
  <gazebo reference="right_rear_link">
    <material>Gazebo/Black</material>
  </gazebo>
  <joint name="right_rear_joint" type="continuous">
    <origin rpy="0 0 0" xyz="-0.15 -0.21 0"/>
    <parent link="base_link"/>
    <child link="right_rear_link"/>
    <axis xyz="0 1 0"/>
    <limit effort="0" lower="-3.14" upper="3.14" velocity="0"/>
  </joint>
  <gazebo reference="right_wheel">
    <material>Gazebo/Red</material>
  </gazebo>
  <!--left flag=1-->
  <!--right flag=-1-->
  <link name="front_steer_left_link">
    <inertial>
      <origin rpy="0 0 0" xyz="0 0 0"/>
      <mass value="1.2963"/>
      <inertia ixx="1.3486705200000003e-05" ixy="0" ixz="0" iyy="1.3486705200000003e-05" iyz="0" izz="1.3486705200000003e-05"/>
    </inertial>
    <visual>
      <origin rpy="0 0 0" xyz="0 0 0"/>
      <geometry>
        <sphere radius="0.0051"/>
      </geometry>
      <material name="black">
        <color rgba="0.0 0.0 0.0 1.0"/>
      </material>
    </visual>
  </link>
  <joint name="front_steer_left_joint" type="revolute">
    <origin rpy="0 0 0" xyz="0.15 0.205 0"/>
    <parent link="base_link"/>
    <child link="front_steer_left_link"/>
    <axis xyz="0 0 1"/>
    <limit effort="0" lower="-0.69" upper="0.69" velocity="0"/>
  </joint>
  <link name="front_left_wheel_link">
    <inertial>
      <origin rpy="1.5707963265 0 0" xyz="0 0 0"/>
      <mass value="0.2963"/>
      <inertia ixx="0.00031157796875000003" ixy="0" ixz="0" iyy="0.00031157796875000003" iyz="0" izz="0.0005787109375"/>
    </inertial>
    <visual>
      <origin rpy="0 0 0" xyz="0 0 0"/>
      <geometry>
        <mesh filename="package://hunter_gazebo/meshes/front_left_wheel_link.STL"/>
      </geometry>
      <material name="black">
        <color rgba="0.0 0.0 0.0 1.0"/>
      </material>
    </visual>
    <collision>
      <origin rpy="0 0 0" xyz="0 0 0"/>
      <geometry>
        <mesh filename="package://hunter_gazebo/meshes/front_left_wheel_link.STL"/>
      </geometry>
    </collision>
  </link>
  <joint name="front_left_wheel_joint" type="continuous">
    <origin rpy="0 0 0" xyz="0 0 0"/>
    <parent link="front_steer_left_link"/>
    <child link="front_left_wheel_link"/>
    <axis xyz="0 1 0"/>
  </joint>
  <gazebo reference="front_left_wheel_link">
    <material>Gazebo/Red</material>
  </gazebo>
  <!--left flag=1-->
  <!--right flag=-1-->
  <link name="front_steer_right_link">
    <inertial>
      <origin rpy="0 0 0" xyz="0 0 0"/>
      <mass value="1.2963"/>
      <inertia ixx="1.3486705200000003e-05" ixy="0" ixz="0" iyy="1.3486705200000003e-05" iyz="0" izz="1.3486705200000003e-05"/>
    </inertial>
    <visual>
      <origin rpy="0 0 0" xyz="0 0 0"/>
      <geometry>
        <sphere radius="0.0051"/>
      </geometry>
      <material name="black">
        <color rgba="0.0 0.0 0.0 1.0"/>
      </material>
    </visual>
  </link>
  <joint name="front_steer_right_joint" type="revolute">
    <origin rpy="0 0 0" xyz="0.15 -0.205 0"/>
    <parent link="base_link"/>
    <child link="front_steer_right_link"/>
    <axis xyz="0 0 1"/>
    <limit effort="0" lower="-0.69" upper="0.69" velocity="0"/>
  </joint>
  <link name="front_right_wheel_link">
    <inertial>
      <origin rpy="1.5707963265 0 0" xyz="0 0 0"/>
      <mass value="0.2963"/>
      <inertia ixx="0.00031157796875000003" ixy="0" ixz="0" iyy="0.00031157796875000003" iyz="0" izz="0.0005787109375"/>
    </inertial>
    <visual>
      <origin rpy="0 0 0" xyz="0 0 0"/>
      <geometry>
        <mesh filename="package://hunter_gazebo/meshes/front_right_wheel_link.STL"/>
      </geometry>
      <material name="black">
        <color rgba="0.0 0.0 0.0 1.0"/>
      </material>
    </visual>
    <collision>
      <origin rpy="0 0 0" xyz="0 0 0"/>
      <geometry>
        <mesh filename="package://hunter_gazebo/meshes/front_right_wheel_link.STL"/>
      </geometry>
    </collision>
  </link>
  <joint name="front_right_wheel_joint" type="continuous">
    <origin rpy="0 0 0" xyz="0 0 0"/>
    <parent link="front_steer_right_link"/>
    <child link="front_right_wheel_link"/>
    <axis xyz="0 1 0"/>
  </joint>
  <gazebo reference="front_right_wheel_link">
    <material>Gazebo/Red</material>
  </gazebo>
  <link name="front_steer_link">
    <inertial>
      <origin rpy="0 0 0" xyz="0 0 0"/>
      <mass value="1.2963"/>
      <inertia ixx="1.3486705200000003e-05" ixy="0" ixz="0" iyy="1.3486705200000003e-05" iyz="0" izz="1.3486705200000003e-05"/>
    </inertial>
    <visual>
      <origin rpy="0 0 0" xyz="0 0 0"/>
      <geometry>
        <sphere radius="0.0051"/>
      </geometry>
      <material name="black">
        <color rgba="0.0 0.0 0.0 1.0"/>
      </material>
    </visual>
  </link>
  <gazebo reference="front_steer_link">
    <material>Gazebo/Red</material>
  </gazebo>
  <joint name="front_steer_joint" type="revolute">
    <origin rpy="0 0 0" xyz="0.15 0 0"/>
    <parent link="base_link"/>
    <child link="front_steer_link"/>
    <axis xyz="0 0 1"/>
    <limit effort="0" lower="-0.69" upper="0.69" velocity="0"/>
  </joint>
  <link name="rear_wheel_link">
    <inertial>
      <origin rpy="0 0 0" xyz="0 0 0"/>
      <mass value="1.2963"/>
      <inertia ixx="1.3486705200000003e-05" ixy="0" ixz="0" iyy="1.3486705200000003e-05" iyz="0" izz="1.3486705200000003e-05"/>
    </inertial>
    <visual>
      <origin rpy="0 0 0" xyz="0 0 0"/>
      <geometry>
        <sphere radius="0.0051"/>
      </geometry>
      <material name="black">
        <color rgba="0.0 0.0 0.0 1.0"/>
      </material>
    </visual>
  </link>
  <joint name="rear_wheel_joint" type="continuous">
    <origin rpy="0 0 0" xyz="-0.15 0 0"/>
    <parent link="base_link"/>
    <child link="rear_wheel_link"/>
    <axis xyz="0 1 0"/>
  </joint>
  <!-- 摄像头安装的z坐标 -->
  <!-- 摄像头关节以及link -->
  <link name="camera">
    <visual>
      <geometry>
        <box size="0.01 0.02 0.03"/>
      </geometry>
      <origin rpy="0.0 0.0 0.0" xyz="0.0 0.0 0.0"/>
      <material name="black"/>
    </visual>
  </link>
  <gazebo reference="camera">
    <material>Gazebo/Black</material>
  </gazebo>
  <joint name="camera2base_link" type="fixed">
    <parent link="base_link"/>
    <child link="camera"/>
    <origin xyz="0.145 0.0 0.045"/>
  </joint>
  <!-- 支架安装的z坐标 -->
  <link name="support">
    <visual>
      <geometry>
        <cylinder length="0.0925" radius="0.01"/>
      </geometry>
      <origin rpy="0.0 0.0 0.0" xyz="0.0 0.0 0.0"/>
      <material name="red">
        <color rgba="0.8 0.2 0.0 0.8"/>
      </material>
    </visual>
  </link>
  <gazebo reference="support">
    <material>Gazebo/Black</material>
  </gazebo>
  <joint name="support2base_link" type="fixed">
    <parent link="base_link"/>
    <child link="support"/>
    <origin xyz="0.0 0.0 0.03"/>
  </joint>
  <!-- 雷达关节以及link -->
  <link name="laser">
    <visual>
      <geometry>
        <cylinder length="0.05" radius="0.03"/>
      </geometry>
      <origin rpy="0.0 0.0 0.0" xyz="0.0 0.0 0.0"/>
      <material name="black"/>
    </visual>
  </link>
  <gazebo reference="laser">
    <material>Gazebo/Black</material>
  </gazebo>
  <joint name="laser2support" type="fixed">
    <parent link="support"/>
    <child link="laser"/>
    <origin xyz="0.0 0.0 0.07125000000000001"/>
  </joint>
</robot>

